1559811490763	Sync.LogManager	DEBUG	Flushing file log
1559811490821	Sync.LogManager	DEBUG	Log cleanup threshold time: 1558947490821
1559811490932	Sync.LogManager	DEBUG	Done deleting files.
1559813367145	Sync.SyncScheduler	DEBUG	Network link status changed to "changed". Offline?: false
1559813367247	Sync.SyncScheduler	DEBUG	Network link status changed to "up". Offline?: false
1559813367247	Sync.SyncScheduler	DEBUG	Network link looks up. Syncing.
1559813367247	Sync.Service	DEBUG	User-Agent: Firefox/67.0 (Intel Mac OS X 10.14) FxSync/1.69.0.20190516215225.desktop
1559813367247	Sync.Service	INFO	Starting sync at 2019-06-06 11:29:27 in browser session DLDB2kz0MYXZ
1559813367248	Sync.SyncScheduler	DEBUG	Clearing sync triggers and the global score.
1559813367249	Sync.Status	INFO	Resetting Status.
1559813367250	Sync.Status	DEBUG	Status.service: success.status_ok => success.status_ok
1559813367759	Sync.SyncScheduler	DEBUG	Network link status changed to "changed". Offline?: false
1559813368122	Sync.SyncScheduler	DEBUG	Network link status changed to "down". Offline?: false
1559813368123	Sync.SyncScheduler	DEBUG	Clearing sync triggers and the global score.
1559813368123	Sync.SyncScheduler	DEBUG	Next sync in 3600000 ms. (why=schedule)
1559813368731	Sync.SyncScheduler	DEBUG	Network link status changed to "changed". Offline?: false
1559813369282	Sync.SyncScheduler	DEBUG	Network link status changed to "up". Offline?: false
1559813369282	Sync.SyncScheduler	DEBUG	Network link looks up. Syncing.
1559813369283	Sync.Service	DEBUG	User-Agent: Firefox/67.0 (Intel Mac OS X 10.14) FxSync/1.69.0.20190516215225.desktop
1559813369283	Sync.Service	INFO	Starting sync at 2019-06-06 11:29:29 in browser session DLDB2kz0MYXZ
1559813369287	Sync.Service	DEBUG	Exception calling anonymous function: LockException: Could not acquire lock. Label: "service.js: sync".(resource://services-sync/util.js:41:5) JS Stack trace: LockException@util.js:41:5
throwLockException@util.js:115:11
WrappedLock@util.js:129:15
_lockedSync@service.js:1164:8
sync/<@service.js:1118:18
WrappedCatch@util.js:103:27
sync@service.js:1119:7
1559813369287	Sync.Service	INFO	Cannot start sync: already syncing?
1559813369400	Sync.SyncScheduler	DEBUG	Network link status changed to "changed". Offline?: false
1559815270187	Sync.SyncScheduler	DEBUG	Network link status changed to "changed". Offline?: false
1559815270688	Sync.SyncScheduler	DEBUG	Network link status changed to "up". Offline?: false
1559815270688	Sync.SyncScheduler	DEBUG	Network link looks up. Syncing.
1559815270689	Sync.Service	DEBUG	User-Agent: Firefox/67.0 (Intel Mac OS X 10.14) FxSync/1.69.0.20190516215225.desktop
1559815270689	Sync.Service	INFO	Starting sync at 2019-06-06 12:01:10 in browser session DLDB2kz0MYXZ
1559815270689	Sync.Service	DEBUG	Exception calling anonymous function: LockException: Could not acquire lock. Label: "service.js: sync".(resource://services-sync/util.js:41:5) JS Stack trace: LockException@util.js:41:5
throwLockException@util.js:115:11
WrappedLock@util.js:129:15
_lockedSync@service.js:1164:8
sync/<@service.js:1118:18
WrappedCatch@util.js:103:27
sync@service.js:1119:7
1559815270689	Sync.Service	INFO	Cannot start sync: already syncing?
1559815270774	Sync.SyncScheduler	DEBUG	Network link status changed to "changed". Offline?: false
1559815271085	Sync.SyncScheduler	DEBUG	Network link status changed to "down". Offline?: false
1559815271085	Sync.SyncScheduler	DEBUG	Clearing sync triggers and the global score.
1559815271085	Sync.SyncScheduler	DEBUG	Next sync in 3600000 ms. (why=schedule)
1559815271689	Sync.SyncScheduler	DEBUG	Network link status changed to "changed". Offline?: false
1559815271795	Sync.Resource	WARN	GET request to https://sync-535-us-west-2.sync.services.mozilla.com/1.5/80856074/info/collections failed: [Exception... "The connection has timed out"  nsresult: "0x804b000e (NS_ERROR_NET_TIMEOUT)"  location: "<unknown>"  data: no] No traceback available
1559815271795	Sync.Status	DEBUG	Status.sync: success.sync => error.login.reason.network
1559815271795	Sync.Status	DEBUG	Status.service: success.status_ok => error.sync.failed
1559815271795	Sync.ErrorHandler	ERROR	Sync encountered an error: [Exception... "The connection has timed out"  nsresult: "0x804b000e (NS_ERROR_NET_TIMEOUT)"  location: "<unknown>"  data: no] No traceback available
1559815271795	Sync.SyncScheduler	DEBUG	Next sync in 3600000 ms. (why=reschedule)
1559815271797	Sync.Service	DEBUG	Exception calling anonymous function: [Exception... "The connection has timed out"  nsresult: "0x804b000e (NS_ERROR_NET_TIMEOUT)"  location: "<unknown>"  data: no] No traceback available
